2020-02-18 13:59:09,490 ERROR: Exception on /certifySelected [POST] [in c:\Users\richa\OneDrive\Projects\AzureCertification\venv\lib\site-packages\flask\app.py:1780]
Traceback (most recent call last):
  File "c:\Users\richa\OneDrive\Projects\AzureCertification\venv\lib\site-packages\flask\app.py", line 2311, in wsgi_app
    response = self.full_dispatch_request()
  File "c:\Users\richa\OneDrive\Projects\AzureCertification\venv\lib\site-packages\flask\app.py", line 1834, in full_dispatch_request
    rv = self.handle_user_exception(e)
  File "c:\Users\richa\OneDrive\Projects\AzureCertification\venv\lib\site-packages\flask\app.py", line 1737, in handle_user_exception
    reraise(exc_type, exc_value, tb)
  File "c:\Users\richa\OneDrive\Projects\AzureCertification\venv\lib\site-packages\flask\_compat.py", line 36, in reraise
    raise value
  File "c:\Users\richa\OneDrive\Projects\AzureCertification\venv\lib\site-packages\flask\app.py", line 1832, in full_dispatch_request
    rv = self.dispatch_request()
  File "c:\Users\richa\OneDrive\Projects\AzureCertification\venv\lib\site-packages\flask\app.py", line 1818, in dispatch_request
    return self.view_functions[rule.endpoint](**req.view_args)
  File "c:\Users\richa\OneDrive\Projects\AzureCertification\app\routes.py", line 596, in certifySelected
    return redirect(url_for('trainingClass'))
  File "c:\Users\richa\OneDrive\Projects\AzureCertification\venv\lib\site-packages\flask\helpers.py", line 356, in url_for
    return appctx.app.handle_url_build_error(error, endpoint, values)
  File "c:\Users\richa\OneDrive\Projects\AzureCertification\venv\lib\site-packages\flask\app.py", line 2080, in handle_url_build_error
    reraise(exc_type, exc_value, tb)
  File "c:\Users\richa\OneDrive\Projects\AzureCertification\venv\lib\site-packages\flask\_compat.py", line 36, in reraise
    raise value
  File "c:\Users\richa\OneDrive\Projects\AzureCertification\venv\lib\site-packages\flask\helpers.py", line 345, in url_for
    force_external=external)
  File "c:\Users\richa\OneDrive\Projects\AzureCertification\venv\lib\site-packages\werkzeug\routing.py", line 2007, in build
    raise BuildError(endpoint, values, method, self)
werkzeug.routing.BuildError: Could not build url for endpoint 'trainingClass'. Did you forget to specify values ['id']?
2020-02-18 13:59:44,002 INFO: Certification startup [in c:\Users\richa\OneDrive\Projects\AzureCertification\app\__init__.py:48]
2020-02-18 14:12:38,610 INFO: Certification startup [in c:\Users\richa\OneDrive\Projects\AzureCertification\app\__init__.py:48]
2020-02-18 14:25:36,930 INFO: Certification startup [in c:\Users\richa\OneDrive\Projects\AzureCertification\app\__init__.py:48]
2020-02-18 14:26:33,969 INFO: Certification startup [in c:\Users\richa\OneDrive\Projects\AzureCertification\app\__init__.py:48]
2020-02-18 14:28:59,303 INFO: Certification startup [in c:\Users\richa\OneDrive\Projects\AzureCertification\app\__init__.py:48]
2020-02-18 14:29:34,236 INFO: Certification startup [in c:\Users\richa\OneDrive\Projects\AzureCertification\app\__init__.py:48]
2020-02-18 14:39:52,941 INFO: Certification startup [in c:\Users\richa\OneDrive\Projects\AzureCertification\app\__init__.py:48]
2020-02-18 14:41:46,047 INFO: Certification startup [in c:\Users\richa\OneDrive\Projects\AzureCertification\app\__init__.py:48]
2020-02-18 14:45:59,850 INFO: Certification startup [in c:\Users\richa\OneDrive\Projects\AzureCertification\app\__init__.py:48]
2020-02-18 14:48:26,957 INFO: Certification startup [in c:\Users\richa\OneDrive\Projects\AzureCertification\app\__init__.py:48]
2020-02-18 14:50:28,562 INFO: Certification startup [in c:\Users\richa\OneDrive\Projects\AzureCertification\app\__init__.py:48]
2020-02-19 10:11:09,157 INFO: Certification startup [in c:\Users\richa\OneDrive\Projects\AzureCertification\app\__init__.py:48]
2020-02-19 10:14:36,812 INFO: Certification startup [in c:\Users\richa\OneDrive\Projects\AzureCertification\app\__init__.py:48]
2020-02-19 12:54:54,642 INFO: Certification startup [in c:\Users\richa\OneDrive\Projects\AzureCertification\app\__init__.py:48]
2020-02-19 12:56:05,390 INFO: Certification startup [in c:\Users\richa\OneDrive\Projects\AzureCertification\app\__init__.py:48]
2020-02-19 12:56:53,760 ERROR: Exception on /reportMenu/10/ [GET] [in c:\Users\richa\OneDrive\Projects\AzureCertification\venv\lib\site-packages\flask\app.py:1780]
Traceback (most recent call last):
  File "c:\Users\richa\OneDrive\Projects\AzureCertification\venv\lib\site-packages\flask\app.py", line 2311, in wsgi_app
    response = self.full_dispatch_request()
  File "c:\Users\richa\OneDrive\Projects\AzureCertification\venv\lib\site-packages\flask\app.py", line 1834, in full_dispatch_request
    rv = self.handle_user_exception(e)
  File "c:\Users\richa\OneDrive\Projects\AzureCertification\venv\lib\site-packages\flask\app.py", line 1737, in handle_user_exception
    reraise(exc_type, exc_value, tb)
  File "c:\Users\richa\OneDrive\Projects\AzureCertification\venv\lib\site-packages\flask\_compat.py", line 36, in reraise
    raise value
  File "c:\Users\richa\OneDrive\Projects\AzureCertification\venv\lib\site-packages\flask\app.py", line 1832, in full_dispatch_request
    rv = self.dispatch_request()
  File "c:\Users\richa\OneDrive\Projects\AzureCertification\venv\lib\site-packages\flask\app.py", line 1818, in dispatch_request
    return self.view_functions[rule.endpoint](**req.view_args)
  File "c:\Users\richa\OneDrive\Projects\AzureCertification\app\routes.py", line 814, in reportMenu
    trainingDates = db.session.query(CertificationClass).join(ShopName,shopNumber==Shop_Number).filter(CertificationClass.id == {id}).all()
NameError: name 'shopNumber' is not defined
2020-02-19 12:57:58,926 INFO: Certification startup [in c:\Users\richa\OneDrive\Projects\AzureCertification\app\__init__.py:48]
2020-02-19 12:58:12,871 ERROR: Exception on /reportMenu/10/ [GET] [in c:\Users\richa\OneDrive\Projects\AzureCertification\venv\lib\site-packages\flask\app.py:1780]
Traceback (most recent call last):
  File "c:\Users\richa\OneDrive\Projects\AzureCertification\venv\lib\site-packages\flask\app.py", line 2311, in wsgi_app
    response = self.full_dispatch_request()
  File "c:\Users\richa\OneDrive\Projects\AzureCertification\venv\lib\site-packages\flask\app.py", line 1834, in full_dispatch_request
    rv = self.handle_user_exception(e)
  File "c:\Users\richa\OneDrive\Projects\AzureCertification\venv\lib\site-packages\flask\app.py", line 1737, in handle_user_exception
    reraise(exc_type, exc_value, tb)
  File "c:\Users\richa\OneDrive\Projects\AzureCertification\venv\lib\site-packages\flask\_compat.py", line 36, in reraise
    raise value
  File "c:\Users\richa\OneDrive\Projects\AzureCertification\venv\lib\site-packages\flask\app.py", line 1832, in full_dispatch_request
    rv = self.dispatch_request()
  File "c:\Users\richa\OneDrive\Projects\AzureCertification\venv\lib\site-packages\flask\app.py", line 1818, in dispatch_request
    return self.view_functions[rule.endpoint](**req.view_args)
  File "c:\Users\richa\OneDrive\Projects\AzureCertification\app\routes.py", line 814, in reportMenu
    trainingDates = db.session.query(CertificationClass).join(ShopName,Shop_Number==shopNumber).filter(CertificationClass.id == {id}).all()
NameError: name 'Shop_Number' is not defined
2020-02-19 13:00:21,070 INFO: Certification startup [in c:\Users\richa\OneDrive\Projects\AzureCertification\app\__init__.py:48]
